Workbook

Sheet HUM TEMP
A1: Nº Muestra | B1: Lata | C1: Plot | D1: Muestreo | E1: Fecha | F1: Peso Tara | G1: Peso Húmedo | H1: Peso Seco | I1: Chala | J1: HUMEDAD | K1: HUM X | L1: DE | M1: Nº muestreo | N1: TSG | O1: PESO GRANO | P1: MF | Q1: MC | R1: Comportamiento Peso | S1: Comportamiento HUM X | T1: Decisión | U1: Column 21
A2: 393 | B2: 43 | C2: 101 | D2: 2 | E2: 43517 | F2: 5211 | G2: 6772 | H2: 6127 | I2: 10 | J2: =+(((G2-F2)-(H2-F2))/(H2-F2))*100 | K2: =AVERAGE(J2:J3) | L2: =_xlfn.STDEV.S(J2,J3) | M2: 2 | O2: =+(H2-F2)/10 | P2: FALSO | Q2: FALSO | R2: Esperado | S2: Esperado | T2: Se descarta
A3: 394 | B3: 44 | C3: 101 | D3: 2 | E3: 43517 | F3: 5218 | G3: 6781 | H3: 6171 | J3: =+(((G3-F3)-(H3-F3))/(H3-F3))*100 | O3: =+(H3-F3)/10 | P3: FALSO | Q3: FALSO | R3: Esperado | S3: Esperado | T3: Se descarta
A4: 1047 | B4: 1 | C4: 101 | D4: 4 | E4: 43524 | F4: 5301 | G4: 7573 | H4: 6914 | I4: 5 | J4: =+(((G4-F4)-(H4-F4))/(H4-F4))*100 | K4: =AVERAGE(J4:J5) | L4: =_xlfn.STDEV.S(J4,J5) | O4: =+(H4-F4)/10 | P4: FALSO | Q4: FALSO | R4: Esperado | S4: Esperado | T4: Se descarta
A5: 1048 | B5: 2 | C5: 101 | D5: 4 | E5: 43524 | F5: 5190 | G5: 7578 | H5: 6882 | J5: =+(((G5-F5)-(H5-F5))/(H5-F5))*100 | O5: =+(H5-F5)/10 | P5: FALSO | Q5: FALSO | R5: Esperado | S5: Esperado | T5: Se descarta
A6: 1697 | B6: 1 | C6: 101 | D6: 6 | E6: 43535 | F6: 5301 | G6: 7320 | H6: 6881 | I6: 5 | J6: =+(((G6-F6)-(H6-F6))/(H6-F6))*100 | K6: =AVERAGE(J6:J7) | L6: =_xlfn.STDEV.S(J6,J7) | O6: =+(H6-F6)/10 | P6: FALSO | Q6: FALSO | R6: No Esperado | S6: Esperado | T6: Se descarta
A7: 1698 | B7: 2 | C7: 101 | D7: 6 | E7: 43535 | F7: 5190 | G7: 7209 | H7: 6778 | J7: =+(((G7-F7)-(H7-F7))/(H7-F7))*100 | O7: =+(H7-F7)/10 | P7: FALSO | Q7: FALSO | R7: No Esperado | S7: Esperado | T7: Se descarta
A8: 2231 | B8: 1 | C8: 101 | D8: 8 | E8: 43550 | F8: 5301 | G8: 7553 | H8: 7123 | J8: =+(((G8-F8)-(H8-F8))/(H8-F8))*100 | K8: =AVERAGE(J8:J9) | L8: =_xlfn.STDEV.S(J8,J9) | O8: =+(H8-F8)/10 | P8: FALSO | Q8: FALSO | R8: Esperado | S8: Esperado | T8: Se descarta
A9: 2232 | B9: 2 | C9: 101 | D9: 8 | E9: 43550 | F9: 5190 | G9: 7463 | H9: 7021 | J9: =+(((G9-F9)-(H9-F9))/(H9-F9))*100 | O9: =+(H9-F9)/10 | P9: FALSO | Q9: FALSO | R9: Esperado | S9: Esperado | T9: Se descarta
A10: 2719 | B10: 91 | C10: 101 | D10: 10 | E10: 43564 | F10: 5252 | G10: 7277 | H10: 7004 | J10: =+(((G10-F10)-(H10-F10))/(H10-F10))*100 | K10: =AVERAGE(J10:J11) | L10: =_xlfn.STDEV.S(J10,J11) | M10: =(K8-K10)/14 | N10: =(K6-K10)/29 | O10: =+(H10-F10)/10 | P10: FALSO | Q10: VERDADERO | R10: Esperado | S10: Esperado | T10: Se descarta
A11: 2720 | B11: 92 | C11: 101 | D11: 10 | E11: 43564 | F11: 5241 | G11: 7344 | H11: 7057 | J11: =+(((G11-F11)-(H11-F11))/(H11-F11))*100 | O11: =+(H11-F11)/10 | P11: FALSO | Q11: FALSO | R11: Esperado | S11: Esperado | T11: Se descarta
A12: 1 | B12: 1 | C12: 102 | D12: 1 | E12: 43514 | F12: 5301 | G12: 7194 | H12: 6963 | I12: 12 | J12: =+(((G12-F12)-(H12-F12))/(H12-F12))*100 | K12: =AVERAGE(J12:J13) | L12: =_xlfn.STDEV.S(J12,J13) | M12: 1 | O12: =+(H12-F12)/10 | P12: FALSO | Q12: VERDADERO | R12: Esperado | S12: No Esperado | T12: Se descarta
A13: 2 | B13: 2 | C13: 102 | D13: 1 | E13: 43514 | F13: 5190 | G13: 6963 | H13: 6746 | J13: =+(((G13-F13)-(H13-F13))/(H13-F13))*100 | O13: =+(H13-F13)/10 | P13: FALSO | Q13: FALSO | R13: Esperado | S13: No Esperado | T13: Se descarta
A14: 655 | B14: 1 | C14: 102 | D14: 3 | E14: 43521 | F14: 5301 | G14: 7084 | H14: 6795 | I14: 9 | J14: =+(((G14-F14)-(H14-F14))/(H14-F14))*100 | K14: =AVERAGE(J14:J15) | L14: =_xlfn.STDEV.S(J14,J15) | O14: =+(H14-F14)/10 | P14: FALSO | Q14: FALSO | R14: No Esperado | S14: No Esperado | T14: Se descarta
A15: 656 | B15: 2 | C15: 102 | D15: 3 | E15: 43521 | F15: 5190 | G15: 7038 | H15: 6739 | J15: =+(((G15-F15)-(H15-F15))/(H15-F15))*100 | O15: =+(H15-F15)/10 | P15: FALSO | Q15: FALSO | R15: No Esperado | S15: No Esperado | T15: Se descarta
A16: 1305 | B16: 1 | C16: 102 | D16: 5 | E16: 43531 | F16: 5301 | G16: 7798 | H16: 7403 | I16: 8 | J16: =+(((G16-F16)-(H16-F16))/(H16-F16))*100 | K16: =AVERAGE(J16:J17) | L16: =_xlfn.STDEV.S(J16,J17) | O16: =+(H16-F16)/10 | P16: FALSO | Q16: FALSO | R16: Esperado | S16: No Esperado | T16: Se descarta
A17: 1306 | B17: 2 | C17: 102 | D17: 5 | E17: 43531 | F17: 5190 | G17: 7592 | H17: 7198 | J17: =+(((G17-F17)-(H17-F17))/(H17-F17))*100 | O17: =+(H17-F17)/10 | P17: FALSO | Q17: FALSO | R17: Esperado | S17: No Esperado | T17: Se descarta
A18: 1955 | B18: 1 | C18: 102 | D18: 7 | E18: 43545 | F18: 5301 | G18: 6797 | H18: 6591 | J18: =+(((G18-F18)-(H18-F18))/(H18-F18))*100 | K18: =AVERAGE(J18:J19) | L18: =_xlfn.STDEV.S(J18,J19) | M18: =+(K16-K18)/14 | O18: =+(H18-F18)/10 | P18: FALSO | Q18: FALSO | R18: No Esperado | S18: No Esperado | T18: Se descarta
A19: 1956 | B19: 2 | C19: 102 | D19: 7 | E19: 43545 | F19: 5190 | G19: 6490 | H19: 6309 | J19: =+(((G19-F19)-(H19-F19))/(H19-F19))*100 | O19: =+(H19-F19)/10 | P19: FALSO | Q19: FALSO | R19: No Esperado | S19: No Esperado | T19: Se descarta
A20: 395 | B20: 45 | C20: 103 | D20: 2 | E20: 43517 | F20: 5211 | G20: 8973 | H20: 7561 | I20: 9 | J20: =+(((G20-F20)-(H20-F20))/(H20-F20))*100 | K20: =AVERAGE(J20:J21) | L20: 0 | M20: 3 | O20: =+(H20-F20)/10 | P20: FALSO | Q20: FALSO | R20: Esperado | S20: Esperado | T20: Dato Válido
A21: 396 | B21: 46 | C21: 103 | D21: 2 | E21: 43517 | F21: 5260 | G21: 8782 | O21: =+(H21-F21)/10 | P21: FALSO | Q21: FALSO | R21: No Esperado | S21: Esperado | T21: Se descarta
A22: 1049 | B22: 3 | C22: 103 | D22: 4 | E22: 43524 | F22: 5258 | G22: 9043 | H22: 7752 | I22: 6 | J22: =+(((G22-F22)-(H22-F22))/(H22-F22))*100 | K22: =AVERAGE(J22:J23) | L22: =_xlfn.STDEV.S(J22,J23) | O22: =+(H22-F22)/10 | P22: FALSO | Q22: FALSO | R22: Esperado | S22: Esperado | T22: Dato Válido
A23: 1050 | B23: 4 | C23: 103 | D23: 4 | E23: 43524 | F23: 5259 | G23: 9268 | H23: 7868 | J23: =+(((G23-F23)-(H23-F23))/(H23-F23))*100 | O23: =+(H23-F23)/10 | P23: FALSO | Q23: FALSO | R23: Esperado | S23: Esperado | T23: Dato Válido
A24: 1699 | B24: 3 | C24: 103 | D24: 6 | E24: 43535 | F24: 5258 | G24: 8960 | H24: 7926 | I24: 7 | J24: =+(((G24-F24)-(H24-F24))/(H24-F24))*100 | K24: =AVERAGE(J24:J25) | L24: =_xlfn.STDEV.S(J24,J25) | O24: =+(H24-F24)/10 | P24: VERDADERO | Q24: FALSO | R24: Esperado | S24: Esperado | T24: Dato Válido
A25: 1700 | B25: 4 | C25: 103 | D25: 6 | E25: 43535 | F25: 5259 | G25: 8837 | H25: 7824 | J25: =+(((G25-F25)-(H25-F25))/(H25-F25))*100 | O25: =+(H25-F25)/10 | P25: FALSO | Q25: FALSO | R25: No Esperado | S25: Esperado | T25: Dato Válido
A26: 2413 | B26: 1 | C26: 103 | D26: 9 | E26: 43557 | F26: 5301 | G26: 8089 | H26: 7674 | J26: =+(((G26-F26)-(H26-F26))/(H26-F26))*100 | K26: =AVERAGE(J26:J27) | L26: =_xlfn.STDEV.S(J26,J27) | O26: =+(H26-F26)/10 | P26: FALSO | Q26: FALSO | R26: No Esperado | S26: Esperado | T26: Dato Válido
A27: 2414 | B27: 2 | C27: 103 | D27: 9 | E27: 43557 | F27: 5190 | G27: 8136 | H27: 7688 | J27: =+(((G27-F27)-(H27-F27))/(H27-F27))*100 | O27: =+(H27-F27)/10 | P27: FALSO | Q27: FALSO | R27: No Esperado | S27: Esperado | T27: Dato Válido
A28: 3061 | B28: 1 | C28: 103 | D28: 12 | E28: 43577 | F28: 5301 | G28: 8387 | H28: 7976 | J28: =+(((G28-F28)-(H28-F28))/(H28-F28))*100 | K28: =AVERAGE(J28:J29) | L28: =_xlfn.STDEV.S(J28,J29) | M28: =+(K26-K28)/20 | N28: =+(K24-K28)/42 | O28: =+(H28-F28)/10 | P28: FALSO | Q28: VERDADERO | R28: Esperado | S28: Esperado | T28: Dato Válido
A29: 3062 | B29: 2 | C29: 103 | D29: 12 | E29: 43577 | F29: 5190 | G29: 8267 | H29: 7837 | J29: =+(((G29-F29)-(H29-F29))/(H29-F29))*100 | O29: =+(H29-F29)/10 | P29: FALSO | Q29: FALSO | R29: Esperado | S29: Esperado | T29: Dato Válido
A30: 3 | B30: 3 | C30: 104 | D30: 1 | E30: 43514 | F30: 5258 | G30: 8211 | H30: 7784 | I30: 8 | J30: =+(((G30-F30)-(H30-F30))/(H30-F30))*100 | K30: =AVERAGE(J30:J31) | L30: =_xlfn.STDEV.S(J30,J31) | M30: 1 | O30: =+(H30-F30)/10 | P30: FALSO | Q30: FALSO | R30: Esperado | S30: No Esperado | T30: Se descarta
A31: 4 | B31: 4 | C31: 104 | D31: 1 | E31: 43514 | F31: 5259 | G31: 8193 | H31: 7767 | J31: =+(((G31-F31)-(H31-F31))/(H31-F31))*100 | O31: =+(H31-F31)/10 | P31: FALSO | Q31: FALSO | R31: Esperado | S31: No Esperado | T31: Se descarta
A32: 657 | B32: 3 | C32: 104 | D32: 3 | E32: 43521 | F32: 5258 | G32: 8136 | H32: 7611 | I32: 7 | J32: =+(((G32-F32)-(H32-F32))/(H32-F32))*100 | K32: =AVERAGE(J32:J33) | L32: =_xlfn.STDEV.S(J32,J33) | O32: =+(H32-F32)/10 | P32: FALSO | Q32: FALSO | R32: No Esperado | S32: No Esperado | T32: Se descarta
A33: 658 | B33: 4 | C33: 104 | D33: 3 | E33: 43521 | F33: 5259 | G33: 8220 | H33: 7682 | J33: =+(((G33-F33)-(H33-F33))/(H33-F33))*100 | O33: =+(H33-F33)/10 | P33: FALSO | Q33: FALSO | R33: No Esperado | S33: No Esperado | T33: Se descarta
A34: 1307 | B34: 3 | C34: 104 | D34: 5 | E34: 43531 | F34: 5258 | G34: 7543 | H34: 7206 | I34: 6 | J34: =+(((G34-F34)-(H34-F34))/(H34-F34))*100 | K34: =AVERAGE(J34:J35) | L34: =_xlfn.STDEV.S(J34,J35) | O34: =+(H34-F34)/10 | P34: FALSO | Q34: FALSO | R34: No Esperado | S34: No Esperado | T34: Se descarta
A35: 1308 | B35: 4 | C35: 104 | D35: 5 | E35: 43531 | F35: 5259 | G35: 7728 | H35: 7346 | J35: =+(((G35-F35)-(H35-F35))/(H35-F35))*100 | O35: =+(H35-F35)/10 | P35: FALSO | Q35: FALSO | R35: No Esperado | S35: No Esperado | T35: Se descarta
A36: 1957 | B36: 3 | C36: 104 | D36: 7 | E36: 43545 | F36: 5258 | G36: 8065 | H36: 7621 | J36: =+(((G36-F36)-(H36-F36))/(H36-F36))*100 | K36: =AVERAGE(J36:J37) | L36: =_xlfn.STDEV.S(J36,J37) | O36: =+(H36-F36)/10 | P36: FALSO | Q36: FALSO | R36: No Esperado | S36: No Esperado | T36: Se descarta
A37: 1958 | B37: 4 | C37: 104 | D37: 7 | E37: 43545 | F37: 5259 | G37: 7916 | H37: 7493 | J37: =+(((G37-F37)-(H37-F37))/(H37-F37))*100 | O37: =+(H37-F37)/10 | P37: FALSO | Q37: FALSO | R37: No Esperado | S37: No Esperado | T37: Se descarta
A38: 2629 | B38: 1 | C38: 104 | D38: 10 | E38: 43564 | F38: 5301 | G38: 8178 | H38: 7763 | J38: =+(((G38-F38)-(H38-F38))/(H38-F38))*100 | K38: =AVERAGE(J38:J39) | L38: =_xlfn.STDEV.S(J38,J39) | M38: =+(K36-K38)/19 | N38: =+(K32-K38)/(E38-E32) | O38: =+(H38-F38)/10 | P38: FALSO | Q38: FALSO | R38: No Esperado | S38: No Esperado | T38: Se descarta
A39: 2630 | B39: 2 | C39: 104 | D39: 10 | E39: 43564 | F39: 5190 | G39: 7858 | H39: 7469 | J39: =+(((G39-F39)-(H39-F39))/(H39-F39))*100 | O39: =+(H39-F39)/10 | P39: FALSO | Q39: FALSO | R39: Esperado | S39: No Esperado | T39: Se descarta
A40: 397 | B40: 47 | C40: 106 | D40: 2 | E40: 43517 | F40: 5258 | G40: 7767 | H40: 7075 | I40: 11 | J40: =+(((G40-F40)-(H40-F40))/(H40-F40))*100 | K40: =AVERAGE(J40:J41) | L40: =_xlfn.STDEV.S(J40,J41) | M40: 2 | O40: =+(H40-F40)/10 | P40: FALSO | Q40: FALSO | R40: No Esperado | S40: Esperado | T40: Dato Válido
...

Sheet ENS TEMP 201819
A1: PLOT | B1: Decisión | C1: BLOC | D1: IBLK | E1: ENTRY | F1: ORIGEN | G1: PEDIGREE | H1: PTAS | I1: VT | J1: GDU_VT | K1: R1 | L1: GDU_R1 | M1: ASI | N1: GDU_ASI | O1: MF | P1: MC | Q1: TSG | R1: Tallo | S1: Roya | T1: MRCV | U1: TIZON | V1: BACT | W1: SG | X1: CH_COMP | Y1: CH_SEMIC | Z1: CH_LAXA | AA1: ESP_CUB | AB1: ESP_SEMI | AC1: ESP_DESC | AD1: GRAN_F | AE1: GRAN_SD
A2: 101 | B2: Se descarta | C2: 1 | D2: 1 | E2: 59 | F2: 17.2802 | G2: LP581xLP562-1-195-1-1 | H2: 47 | I2: 43467 | J2: 1080.75 | K2: 43468 | L2: 1094.25 | M2: 13.5 | N2: ='ENS TEMP 201819'!$L253-'ENS TEMP 201819'!$J253 | O2: 43517 | P2: 43566 | Q2: 0.405 | X2: .
A3: 102 | B3: Se descarta | C3: 1 | D3: 1 | E3: 104 | F3: 17.2898 | G3: LP 59 | I3: 43460 | J3: 959.9 | K3: 43461 | L3: 977.15 | M3: 17.25 | N3: ='ENS TEMP 201819'!$L50-'ENS TEMP 201819'!$J50 | O3: null | P3: null | Q3: null | X3: .
A4: 103 | B4: Plot Válido | C4: 1 | D4: 1 | E4: 62 | F4: 17.2808 | G4: [BSGA] 04.4071-1.1.1.1.1.#.# | I4: 43466 | J4: 1059.6 | K4: 43468 | L4: 1094.25 | M4: 34.65 | N4: ='ENS TEMP 201819'!$L224-'ENS TEMP 201819'!$J224 | O4: 43537 | P4: 43585 | Q4: 0.555 | X4: .
A5: 104 | B5: Se descarta | C5: 1 | D5: 1 | E5: 83 | F5: 17.2856 | G5: [AX889] 04.725-1.1.1.1.1.# | I5: 43460 | J5: 959.9 | K5: 43459 | L5: 943.6 | M5: -16.3 | N5: ='ENS TEMP 201819'!$L51-'ENS TEMP 201819'!$J51 | O5: 43521 | P5: 43564 | Q5: 0.12314788 | X5: .
A6: 105 | B6: Se descarta | C6: 1 | D6: 1 | E6: 124 | F6: 17.2938//BEBA | G6: LP 561 | N6: ='ENS TEMP 201819'!$L325-'ENS TEMP 201819'!$J325 | X6: .
A7: 106 | B7: Plot Válido | C7: 1 | D7: 1 | E7: 109 | F7: 17.2908 | G7: LP 214 | H7: 45 | I7: 43466 | J7: 1059.6 | K7: 43466 | L7: 1059.6 | M7: 0 | N7: ='ENS TEMP 201819'!$L225-'ENS TEMP 201819'!$J225 | O7: 43521 | P7: 43553 | Q7: 0.657 | X7: .
A8: 107 | B8: Plot Válido | C8: 1 | D8: 1 | E8: 27 | F8: 17.2610 | G8: LÑnea CFR#1#1#1#1 | I8: 43464 | J8: 1028.65 | K8: 43465 | L8: 1041.6 | M8: 12.95 | N8: ='ENS TEMP 201819'!$L154-'ENS TEMP 201819'!$J154 | O8: 43520 | P8: 43564 | Q8: 0.559 | X8: .
A9: 108 | B9: Plot Válido | C9: 1 | D9: 1 | E9: 22 | F9: 17.2600 | G9: bulk 04.1973-119-1-1-1#1#1 | H9: 46 | I9: 43463 | J9: 1013.8 | K9: 43463 | L9: 1013.8 | M9: 0 | N9: ='ENS TEMP 201819'!$L130-'ENS TEMP 201819'!$J130 | O9: 43526 | P9: 43595 | Q9: 0.483 | X9: .
A10: 109 | B10: Plot Válido | C10: 1 | D10: 1 | E10: 39 | F10: 17.2638 | G10: 94.1234-1-1#-1#1-2#1#3#1#1#1#1#1#1-1 | H10: 57 | I10: 43462 | J10: 995.2 | K10: 43463 | L10: 1013.8 | M10: 18.6 | N10: ='ENS TEMP 201819'!$L99-'ENS TEMP 201819'!$J99 | O10: 43518 | P10: 43564 | Q10: 0.489 | X10: .
A11: 110 | B11: Plot Válido | C11: 1 | D11: 1 | E11: 108 | F11: 17.2906 | G11: LP 212 | H11: 52 | I11: 43465 | J11: 1041.6 | K11: 43464 | L11: 1028.65 | M11: -12.95 | N11: ='ENS TEMP 201819'!$L198-'ENS TEMP 201819'!$J198 | O11: 43523 | P11: 43575 | Q11: 0.459 | X11: .
A12: 111 | B12: Plot Válido | C12: 1 | D12: 1 | E12: 25 | F12: 17.2606 | G12: 99.6113x99.6112#1-36-1-1-1-1#1#1#1 | H12: 48 | I12: 43467 | J12: 1080.75 | K12: 43467 | L12: 1080.75 | M12: 0 | N12: ='ENS TEMP 201819'!$L254-'ENS TEMP 201819'!$J254 | O12: 43544 | P12: 43595 | Q12: 0.406 | X12: .
A13: 112 | B13: Se descarta | C13: 1 | D13: 1 | E13: 87 | F13: 17.2864 | G13: [CDP] 04.649-1.1.1.1.1.# | H13: 51 | I13: 43463 | J13: 1013.8 | K13: 43464 | L13: 1028.65 | M13: 14.85 | N13: ='ENS TEMP 201819'!$L131-'ENS TEMP 201819'!$J131 | O13: 43519 | P13: 43569 | Q13: 0.391 | X13: .
A14: 113 | B14: Plot Válido | C14: 1 | D14: 2 | E14: 43 | F14: 17.2646 | G14: 00.6332-3#1#1#1#1#1#1#1#1-1 | H14: 48 | I14: 43471 | J14: 1136.6 | K14: 43473 | L14: 1169.35 | M14: 32.75 | N14: ='ENS TEMP 201819'!$L319-'ENS TEMP 201819'!$J319 | O14: 43532 | P14: 43598 | Q14: 0.327 | R14: 5 | S14: 1 H | V14: 1 | X14: .
A15: 114 | B15: Se descarta | C15: 1 | D15: 2 | E15: 40 | F15: 172640 | G15: 94.1283-1-1#-1#1#1-3#1#1#1#1#1#1#1#1-1 | H15: 44 | I15: 43471 | J15: 1136.6 | K15: 43473 | L15: 1169.35 | M15: 32.75 | N15: ='ENS TEMP 201819'!$L320-'ENS TEMP 201819'!$J320 | O15: 43530 | P15: 43605 | Q15: 0.524 | R15: 5 | S15: 1 H | V15: 1 | X15: .
A16: 115 | B16: Plot Válido | C16: 1 | D16: 2 | E16: 79 | F16: 17.2846 | G16: [AX882] 04.755-1.1.1.1.1.# | H16: 44 | I16: 43464 | J16: 1028.65 | K16: 43464 | L16: 1028.65 | M16: 0 | N16: ='ENS TEMP 201819'!$L155-'ENS TEMP 201819'!$J155 | O16: 43525 | P16: 43552 | Q16: 0.666 | X16: .
A17: 116 | B17: Plot Válido | C17: 1 | D17: 2 | E17: 2 | F17: 17.2558 | G17: BKBS13idprov901947-1-30 -1-1@-1#1 | H17: 51 | I17: 43462 | J17: 995.2 | K17: 43463 | L17: 1013.8 | M17: 18.6 | N17: ='ENS TEMP 201819'!$L100-'ENS TEMP 201819'!$J100 | O17: 43519 | P17: 43573 | Q17: 0.675 | X17: .
A18: 117 | B18: Se descarta | C18: 1 | D18: 2 | E18: 119 | F18: 17.2928 | G18: LP 1996 | H18: 42 | I18: 43470 | J18: 1122.85 | K18: 43473 | L18: 1169.35 | M18: 46.5 | N18: ='ENS TEMP 201819'!$L310-'ENS TEMP 201819'!$J310 | O18: 43517 | P18: 43569 | Q18: 0.389 | R18: 5 AC | S18: 1,5 H | V18: 0 | X18: .
A19: 118 | B19: Se descarta | C19: 1 | D19: 2 | E19: 144 | F19: 17.2976 | G19: LP 917 | H19: 46 | I19: 43469 | J19: 1108.05 | K19: 43468 | L19: 1094.25 | M19: -13.8 | N19: ='ENS TEMP 201819'!$L292-'ENS TEMP 201819'!$J292 | O19: 43527 | P19: 43596 | Q19: 0.5 | X19: .
A20: 119 | B20: Plot Válido | C20: 1 | D20: 2 | E20: 164 | F20: 17.3016 | G20: P465 | H20: 39 | I20: 43466 | J20: 1059.6 | K20: 43466 | L20: 1059.6 | M20: 0 | N20: ='ENS TEMP 201819'!$L226-'ENS TEMP 201819'!$J226 | O20: 43531 | P20: 43585 | Q20: 0.384 | X20: .
A21: 120 | B21: Plot Válido | C21: 1 | D21: 2 | E21: 7 | F21: 17.2568 | G21: BKBS13idprov901947-1-117 -1-1-1-1#1 | H21: 46 | I21: 43463 | J21: 1013.8 | K21: 43466 | L21: 1059.6 | M21: 45.8 | N21: ='ENS TEMP 201819'!$L132-'ENS TEMP 201819'!$J132 | O21: 43531 | P21: 43585 | Q21: 0.402 | X21: .
A22: 121 | B22: Plot Válido | C22: 1 | D22: 2 | E22: 8 | F22: 17.2570 | G22: BKBS13idprov901947-1-119 -1-1@-1#1 | H22: 41 | I22: 43463 | J22: 1013.8 | K22: 43464 | L22: 1028.65 | M22: 14.85 | N22: ='ENS TEMP 201819'!$L133-'ENS TEMP 201819'!$J133 | O22: 43541 | P22: 43605 | Q22: 0.377 | X22: .
A23: 122 | B23: Plot Válido | C23: 1 | D23: 2 | E23: 122 | F23: 17.2934//FONT21 | G23: LP 126 | H23: 46 | I23: 43466 | J23: 1059.6 | K23: 43466 | L23: 1059.6 | M23: 0 | N23: ='ENS TEMP 201819'!$L227-'ENS TEMP 201819'!$J227 | O23: 43518 | P23: 43553 | Q23: 0.63 | X23: .
A24: 123 | B24: Plot Válido | C24: 1 | D24: 2 | E24: 153 | F24: 17.2994 | G24: LP 32 | H24: 38 | I24: 43462 | J24: 995.2 | K24: 43462 | L24: 995.2 | M24: 0 | N24: ='ENS TEMP 201819'!$L101-'ENS TEMP 201819'!$J101 | O24: 43516 | P24: 43555 | Q24: 0.571 | X24: .
A25: 124 | B25: Se descarta | C25: 1 | D25: 2 | E25: 54 | F25: 17.2700 | G25: (7310x7266)-1-46 | H25: 51 | I25: 43464 | J25: 1028.65 | K25: 43463 | L25: 1013.8 | M25: -14.85 | N25: ='ENS TEMP 201819'!$L156-'ENS TEMP 201819'!$J156 | O25: 43514 | P25: 43610 | Q25: 0.433 | X25: .
A26: 125 | B26: Plot Válido | C26: 1 | D26: 3 | E26: 12 | F26: 17.2578 | G26: BKBS13idprov901947-1-192 -1-1-1-1#1 | I26: 43460 | J26: 959.9 | K26: 43460 | L26: 959.9 | M26: 0 | N26: ='ENS TEMP 201819'!$L52-'ENS TEMP 201819'!$J52 | O26: 43512 | P26: 43555 | Q26: 0.499 | X26: .
A27: 126 | B27: Se descarta | C27: 1 | D27: 3 | E27: 110 | F27: 17.2910 | G27: LP 220 | I27: 43461 | J27: 977.15 | K27: 43459 | L27: 943.6 | M27: -33.55 | N27: ='ENS TEMP 201819'!$L83-'ENS TEMP 201819'!$J83 | O27: 43517 | P27: 43575 | Q27: 0.239 | X27: .
A28: 127 | B28: Se descarta | C28: 1 | D28: 3 | E28: 17 | F28: 17.2588 | G28: bulk 04.1973-54-1-1-1#1 | I28: 43469 | J28: 1108.05 | K28: 43473 | L28: 1169.35 | M28: 61.3 | N28: ='ENS TEMP 201819'!$L293-'ENS TEMP 201819'!$J293 | O28: 43539 | P28: 43581 | Q28: 0.842 | X28: .
A29: 128 | B29: Plot Válido | C29: 1 | D29: 3 | E29: 160 | F29: 17.3008//NN15.705 | G29: 4068 (Sint. Cuarentin x L 1571) | I29: 43460 | J29: 959.9 | K29: 43460 | L29: 959.9 | M29: 0 | N29: ='ENS TEMP 201819'!$L53-'ENS TEMP 201819'!$J53 | O29: 43531 | P29: 43583 | Q29: 0.409 | X29: .
A30: 129 | B30: Plot Válido | C30: 1 | D30: 3 | E30: 29 | F30: 17.2614 | G30: 99.5905-1-1-1-1-1#1-1#1#1#1-1 | I30: 43460 | J30: 959.9 | K30: 43461 | L30: 977.15 | M30: 17.25 | N30: ='ENS TEMP 201819'!$L54-'ENS TEMP 201819'!$J54 | O30: 43514 | P30: 43545 | Q30: 0.728 | X30: .
A31: 130 | B31: Plot Válido | C31: 1 | D31: 3 | E31: 73 | F31: 17.2832 | G31: [SynSDSP] 04.4045-1.1.1.1.1.# | I31: 43466 | J31: 1059.6 | K31: 43466 | L31: 1059.6 | M31: 0 | N31: ='ENS TEMP 201819'!$L228-'ENS TEMP 201819'!$J228 | O31: 43526 | P31: 43554 | Q31: 0.915 | X31: .
A32: 131 | B32: Se descarta | C32: 1 | D32: 3 | E32: 36 | F32: 17.2632 | G32: 99.5736-4 LP611V X LP613-2-1-1-1#1#1#1-1 | I32: 43462 | J32: 995.2 | K32: 43464 | L32: 1028.65 | M32: 33.45 | N32: ='ENS TEMP 201819'!$L102-'ENS TEMP 201819'!$J102 | O32: 43523 | P32: 43570 | Q32: 0.701 | X32: .
A33: 132 | B33: Se descarta | C33: 1 | D33: 3 | E33: 44 | F33: 17.2648 | G33: 00.6334-1#1#1#1#1#1#1#1#1-1 | I33: 43471 | J33: 1136.6 | K33: 43473 | L33: 1169.35 | M33: 32.75 | N33: ='ENS TEMP 201819'!$L321-'ENS TEMP 201819'!$J321 | O33: 43538 | P33: 43599 | Q33: 0.34 | X33: .
A34: 133 | B34: Plot Válido | C34: 1 | D34: 3 | E34: 81 | F34: 17.2852 | G34: [AX889] 04.715-1.1.1.1.1.# | I34: 43462 | J34: 995.2 | K34: 43462 | L34: 995.2 | M34: 0 | N34: ='ENS TEMP 201819'!$L103-'ENS TEMP 201819'!$J103 | O34: 43523 | P34: 43558 | Q34: 0.661 | X34: .
A35: 134 | B35: Plot Válido | C35: 1 | D35: 3 | E35: 152 | F35: 17.2992 | G35: LP 2542 | I35: 43462 | J35: 995.2 | K35: 43462 | L35: 995.2 | M35: 0 | N35: ='ENS TEMP 201819'!$L104-'ENS TEMP 201819'!$J104 | O35: 43521 | P35: 43554 | Q35: 0.654 | X35: .
A36: 135 | B36: Se descarta | C36: 1 | D36: 3 | E36: 24 | F36: 17.2604 | G36: bulk 04.1973-143-1-1-1#1#1 | I36: 43467 | J36: 1080.75 | K36: 43467 | L36: 1080.75 | M36: 0 | N36: ='ENS TEMP 201819'!$L255-'ENS TEMP 201819'!$J255 | O36: 43529 | P36: 43605 | Q36: 0.443 | X36: .
A37: 136 | B37: Plot Válido | C37: 1 | D37: 3 | E37: 126 | F37: 17.2942 | G37: LP 122-2 | I37: 43468 | J37: 1094.25 | K37: 43471 | L37: 1136.6 | M37: 42.35 | N37: ='ENS TEMP 201819'!$L278-'ENS TEMP 201819'!$J278 | O37: 43531 | P37: 43601 | Q37: 0.389 | X37: .
A38: 137 | B38: Se descarta | C38: 1 | D38: 4 | E38: 56 | F38: 17.2796 | G38: LP581xLP562-1-42-1-1 | I38: 43465 | J38: 1041.6 | K38: 43465 | L38: 1041.6 | M38: 0 | N38: ='ENS TEMP 201819'!$L199-'ENS TEMP 201819'!$J199 | O38: 43525 | P38: 43605 | Q38: 0.485 | X38: .
A39: 138 | B39: Se descarta | C39: 1 | D39: 4 | E39: 89 | F39: 17.2868 | G39: [DK638] 04.631-1.1.1.1.1.# | I39: 43467 | J39: 1080.75 | K39: 43468 | L39: 1094.25 | M39: 13.5 | N39: ='ENS TEMP 201819'!$L256-'ENS TEMP 201819'!$J256 | O39: 43538 | P39: 43583 | Q39: 0.604 | X39: .
A40: 139 | B40: Plot Válido | C40: 1 | D40: 4 | E40: 34 | F40: 17.2628 | G40: 93.1849-3-1-1-1#2#1-1##1#1#1#1#1#1#1-1 | I40: 43464 | J40: 1028.65 | K40: 43464 | L40: 1028.65 | M40: 0 | N40: ='ENS TEMP 201819'!$L157-'ENS TEMP 201819'!$J157 | O40: 43514 | P40: 43575 | Q40: 0.368 | X40: .
...

Sheet Tabla dinámica TSG
E2: Fecha MC | F2: Hum MC | G2: TSG
E3: =VLOOKUP(A3,$H$2:$J$203,3,FALSE) | F3: =VLOOKUP(A3,$H$2:$J$203,2,FALSE) | G3: =(C3-F3)/(E3-B3)
E4: =VLOOKUP(A4,$H$2:$J$203,3,FALSE) | F4: =VLOOKUP(A4,$H$2:$J$203,2,FALSE) | G4: =(C4-F4)/(E4-B4)
E5: =VLOOKUP(A5,$H$2:$J$203,3,FALSE) | F5: =VLOOKUP(A5,$H$2:$J$203,2,FALSE) | G5: =(C5-F5)/(E5-B5)
E6: =VLOOKUP(A6,$H$2:$J$203,3,FALSE) | F6: =VLOOKUP(A6,$H$2:$J$203,2,FALSE) | G6: =(C6-F6)/(E6-B6)
E7: =VLOOKUP(A7,$H$2:$J$203,3,FALSE) | F7: =VLOOKUP(A7,$H$2:$J$203,2,FALSE) | G7: =(C7-F7)/(E7-B7)
E8: =VLOOKUP(A8,$H$2:$J$203,3,FALSE) | F8: =VLOOKUP(A8,$H$2:$J$203,2,FALSE) | G8: =(C8-F8)/(E8-B8)
E9: =VLOOKUP(A9,$H$2:$J$203,3,FALSE) | F9: =VLOOKUP(A9,$H$2:$J$203,2,FALSE) | G9: =(C9-F9)/(E9-B9)
E10: =VLOOKUP(A10,$H$2:$J$203,3,FALSE) | F10: =VLOOKUP(A10,$H$2:$J$203,2,FALSE) | G10: =(C10-F10)/(E10-B10)
E11: =VLOOKUP(A11,$H$2:$J$203,3,FALSE) | F11: =VLOOKUP(A11,$H$2:$J$203,2,FALSE) | G11: =(C11-F11)/(E11-B11)
E12: =VLOOKUP(A12,$H$2:$J$203,3,FALSE) | F12: =VLOOKUP(A12,$H$2:$J$203,2,FALSE) | G12: =(C12-F12)/(E12-B12)
E13: =VLOOKUP(A13,$H$2:$J$203,3,FALSE) | F13: =VLOOKUP(A13,$H$2:$J$203,2,FALSE) | G13: =(C13-F13)/(E13-B13)
E14: =VLOOKUP(A14,$H$2:$J$203,3,FALSE) | F14: =VLOOKUP(A14,$H$2:$J$203,2,FALSE) | G14: =(C14-F14)/(E14-B14)
... E196: =VLOOKUP(A196,$H$2:$J$203,3,FALSE) | F196: =VLOOKUP(A196,$H$2:$J$203,2,FALSE) | G196: =(C196-F196)/(E196-B196)

Sheet Tabla dinámica TEMP
A1: Año | B1: Ensayo | C1: Localidad
A2: 2019 | B2: Temprano | C2: Pergamino
A3: 2018 | B3: Temprano | C3: Pergamino
A4: 2018 | B4: Temprano | C4: Pergamino
A5: 2018 | B5: Temprano | C5: Pergamino
A6: 2018 | B6: Temprano | C6: Pergamino
A7: 2018 | B7: Temprano | C7: Pergamino
A8: 2018 | B8: Temprano | C8: Pergamino
A9: 2018 | B9: Temprano | C9: Pergamino
A10: 2018 | B10: Temprano | C10: Pergamino
A11: 2018 | B11: Temprano | C11: Pergamino
A12: 2018 | B12: Temprano | C12: Pergamino
A13: 2018 | B13: Temprano | C13: Pergamino
... A51: 2018 | B51: Temprano | C51: Pergamino

Sheet HUM TARD
A1: Nº Muestra | B1: Lata | C1: PLOT | D1: Muestreo | E1: Fecha | F1: Peso Tara | G1: Peso Húmedo | H1: Peso Seco | I1: Chala | J1: HUM | K1: MF1 | L1: HUM X | M1: DE | N1: Columna1 | O1: TSG | P1: Peso Seco Mil | Q1: P_S_Mil | R1: MF | S1: MC | T1: Comportamiento Peso | U1: Comportamiento HM X | V1: Decisión
A2: 3245 | B2: 1 | C2: 101 | D2: 13 | E2: 43587 | F2: 5301 | G2: 8480 | H2: 7635 | I2: 1 | J2: =+(((G2-F2)-(H2-F2))/(H2-F2))*100 | K2: 1/4 | L2: =AVERAGE(J2:J3) | M2: =_xlfn.STDEV.S(J2,J3) | N2: 1 | P2: =+(((H2-F2)/1000)*1000)/10 | Q2: =AVERAGE(P2:P3) | R2: VERDADERO | S2: FALSO | T2: Esperado | U2: Esperado | V2: Plot Válido
A3: 3246 | B3: 2 | C3: 101 | D3: 13 | E3: 43587 | F3: 5190 | G3: 8093 | H3: 7277 | J3: =+(((G3-F3)-(H3-F3))/(H3-F3))*100 | P3: =+(((H3-F3)/1000)*1000)/10 | R3: FALSO | S3: FALSO | T3: Esperado | U3: Esperado | V3: Plot Válido
A4: 3971 | B4: 1 | C4: 101 | D4: 15 | E4: 43599 | F4: 5301 | G4: 9609 | H4: 8132 | J4: =+(((G4-F4)-(H4-F4))/(H4-F4))*100 | K4: 10/5 | L4: =AVERAGE(J4:J5) | M4: =_xlfn.STDEV.S(J4,J5) | P4: =+(((H4-F4)/1000)*1000)/10 | Q4: =AVERAGE(P4:P5) | R4: FALSO | S4: FALSO | T4: Esperado | U4: No Esperado | V4: Plot Válido
A5: 3972 | B5: 2 | C5: 101 | D5: 15 | E5: 43599 | F5: 5190 | G5: 8993 | H5: 7675 | J5: =+(((G5-F5)-(H5-F5))/(H5-F5))*100 | P5: =+(((H5-F5)/1000)*1000)/10 | R5: FALSO | S5: FALSO | T5: Esperado | U5: No Esperado | V5: Plot Válido
A6: 4617 | B6: 1 | C6: 101 | D6: 17 | E6: 43619 | F6: 5301 | G6: 6901 | H6: 6651 | J6: =+(((G6-F6)-(H6-F6))/(H6-F6))*100 | L6: =AVERAGE(J6:J7) | M6: =_xlfn.STDEV.S(J6,J7) | P6: =+(((H6-F6)/1000)*1000)/10 | Q6: =AVERAGE(P6:P7) | R6: FALSO | S6: FALSO | T6: No Esperado | U6: Esperado | V6: Plot Válido
A7: 4618 | B7: 2 | C7: 101 | D7: 17 | E7: 43619 | F7: 5190 | G7: 6731 | H7: 6495 | J7: =+(((G7-F7)-(H7-F7))/(H7-F7))*100 | P7: =+(((H7-F7)/1000)*1000)/10 | R7: FALSO | S7: FALSO | T7: No Esperado | U7: Esperado | V7: Plot Válido
A8: 5263 | B8: 1 | C8: 101 | D8: 19 | E8: 43637 | F8: 5301 | G8: 8381 | H8: 7759 | I8: 9/10 | J8: =+(((G8-F8)-(H8-F8))/(H8-F8))*100 | L8: =AVERAGE(J8:J9) | M8: =_xlfn.STDEV.S(J8,J9) | P8: =+(((H8-F8)/1000)*1000)/10 | Q8: =AVERAGE(P8:P9) | R8: FALSO | S8: FALSO | T8: Esperado | U8: No Esperado | V8: Plot Válido
A9: 5264 | B9: 2 | C9: 101 | D9: 19 | E9: 43637 | F9: 5190 | G9: 8166 | H9: 7567 | J9: =+(((G9-F9)-(H9-F9))/(H9-F9))*100 | P9: =+(((H9-F9)/1000)*1000)/10 | R9: FALSO | S9: FALSO | T9: Esperado | U9: No Esperado | V9: Plot Válido
A10: 5509 | B10: 1 | C10: 101 | D10: 20 | E10: 43649 | F10: 5301 | G10: 8263 | H10: 7715 | I10: 9 | J10: =+(((G10-F10)-(H10-F10))/(H10-F10))*100 | L10: =AVERAGE(J10:J11) | M10: =_xlfn.STDEV.S(J10,J11) | P10: =+(((H10-F10)/1000)*1000)/10 | Q10: =AVERAGE(P10:P11) | R10: FALSO | S10: FALSO | T10: Esperado | U10: No Esperado | V10: Plot Válido
A11: 5510 | B11: 2 | C11: 101 | D11: 20 | E11: 43649 | F11: 5190 | G11: 8070 | H11: 7542 | J11: =+(((G11-F11)-(H11-F11))/(H11-F11))*100 | P11: =+(((H11-F11)/1000)*1000)/10 | R11: FALSO | S11: FALSO | T11: Esperado | U11: No Esperado | V11: Plot Válido
A12: 5755 | B12: 1 | C12: 101 | D12: 22 | E12: 43685 | F12: 5301 | G12: 7766 | H12: 7421 | I12: 6 | J12: =+(((G12-F12)-(H12-F12))/(H12-F12))*100 | L12: =AVERAGE(J12:J13) | M12: =_xlfn.STDEV.S(J12,J13) | N12: =(L10-L12)/36 | O12: =(L8-L12)/48 | P12: =+(((H12-F12)/1000)*1000)/10 | Q12: =AVERAGE(P12:P13) | R12: FALSO | S12: VERDADERO | T12: No Esperado | U12: Esperado | V12: Plot Válido
A13: 5756 | B13: 1 | C13: 101 | D13: 22 | E13: 43685 | F13: 5301 | G13: 7801 | H13: 7462 | J13: =+(((G13-F13)-(H13-F13))/(H13-F13))*100 | P13: =+(((H13-F13)/1000)*1000)/10 | R13: FALSO | S13: FALSO | T13: No Esperado | U13: Esperado | V13: Plot Válido
A14: 3247 | B14: 3 | C14: 102 | D14: 13 | E14: 43587 | F14: 5258 | G14: 9293 | H14: 7999 | I14: 1 | J14: =+(((G14-F14)-(H14-F14))/(H14-F14))*100 | K14: 1/2 | L14: =AVERAGE(J14:J15) | M14: =_xlfn.STDEV.S(J14,J15) | N14: 1 | P14: =+(((H14-F14)/1000)*1000)/10 | Q14: =AVERAGE(P14:P15) | R14: FALSO | S14: FALSO | T14: Esperado | U14: Esperado | V14: Plot Válido
A15: 3248 | B15: 4 | C15: 102 | D15: 13 | E15: 43587 | F15: 5259 | G15: 9138 | H15: 7924 | J15: =+(((G15-F15)-(H15-F15))/(H15-F15))*100 | P15: =+(((H15-F15)/1000)*1000)/10 | R15: FALSO | S15: FALSO | T15: Esperado | U15: Esperado | V15: Plot Válido
A16: 3973 | B16: 3 | C16: 102 | D16: 15 | E16: 43599 | F16: 5258 | G16: 8236 | H16: 7373 | J16: =+(((G16-F16)-(H16-F16))/(H16-F16))*100 | K16: MF* | L16: =AVERAGE(J16:J17) | M16: =_xlfn.STDEV.S(J16,J17) | P16: =+(((H16-F16)/1000)*1000)/10 | Q16: =AVERAGE(P16:P17) | R16: FALSO | S16: FALSO | T16: Esperado | U16: Esperado | V16: Plot Válido
A17: 3974 | B17: 4 | C17: 102 | D17: 15 | E17: 43599 | F17: 5259 | G17: 8423 | H17: 7537 | J17: =+(((G17-F17)-(H17-F17))/(H17-F17))*100 | P17: =+(((H17-F17)/1000)*1000)/10 | R17: FALSO | S17: FALSO | T17: Esperado | U17: Esperado | V17: Plot Válido
A18: 4619 | B18: 3 | C18: 102 | D18: 17 | E18: 43619 | F18: 5258 | G18: 7811 | H18: 7349 | J18: =+(((G18-F18)-(H18-F18))/(H18-F18))*100 | L18: =AVERAGE(J18:J19) | M18: =_xlfn.STDEV.S(J18,J19) | P18: =+(((H18-F18)/1000)*1000)/10 | Q18: =AVERAGE(P18:P19) | R18: FALSO | S18: FALSO | T18: Esperado | U18: Esperado | V18: Plot Válido
A19: 4620 | B19: 4 | C19: 102 | D19: 17 | E19: 43619 | F19: 5259 | G19: 7715 | H19: 7282 | J19: =+(((G19-F19)-(H19-F19))/(H19-F19))*100 | P19: =+(((H19-F19)/1000)*1000)/10 | R19: FALSO | S19: FALSO | T19: Esperado | U19: Esperado | V19: Plot Válido
A20: 5265 | B20: 3 | C20: 102 | D20: 19 | E20: 43637 | F20: 5258 | G20: 9414 | H20: 8355 | I20: 6 | J20: =+(((G20-F20)-(H20-F20))/(H20-F20))*100 | L20: =AVERAGE(J20:J21) | M20: =_xlfn.STDEV.S(J20,J21) | P20: =+(((H20-F20)/1000)*1000)/10 | Q20: =AVERAGE(P20:P21) | R20: VERDADERO | S20: FALSO | T20: Esperado | U20: No Esperado | V20: Plot Válido
A21: 5266 | B21: 4 | C21: 102 | D21: 19 | E21: 43637 | F21: 5259 | G21: 9455 | H21: 8361 | J21: =+(((G21-F21)-(H21-F21))/(H21-F21))*100 | P21: =+(((H21-F21)/1000)*1000)/10 | R21: FALSO | S21: FALSO | T21: Esperado | U21: No Esperado | V21: Plot Válido
A22: 5757 | B22: 2 | C22: 102 | D22: 22 | E22: 43685 | F22: 5190 | G22: 7725 | H22: 7370 | I22: 6 | J22: =+(((G22-F22)-(H22-F22))/(H22-F22))*100 | L22: =AVERAGE(J22:J23) | M22: =_xlfn.STDEV.S(J22,J23) | N22: =(L18-L22)/66 | O22: =(L16-L22)/86 | P22: =+(((H22-F22)/1000)*1000)/10 | Q22: =AVERAGE(P22:P23) | R22: FALSO | S22: FALSO | T22: No Esperado | U22: Esperado | V22: Plot Válido
A23: 5758 | B23: 2 | C23: 102 | D23: 22 | E23: 43685 | F23: 5190 | G23: 7597 | H23: 7266 | J23: =+(((G23-F23)-(H23-F23))/(H23-F23))*100 | P23: =+(((H23-F23)/1000)*1000)/10 | R23: FALSO | S23: FALSO | T23: No Esperado | U23: Esperado | V23: Plot Válido
A24: 3627 | B24: 49 | C24: 103 | D24: 14 | E24: 43591 | F24: 5203 | G24: 7980 | H24: 7170 | I24: 2 | J24: =+(((G24-F24)-(H24-F24))/(H24-F24))*100 | K24: MF | L24: =AVERAGE(J24:J25) | M24: =_xlfn.STDEV.S(J24,J25) | N24: 2 | P24: =+(((H24-F24)/1000)*1000)/10 | Q24: =AVERAGE(P24:P25) | R24: FALSO | S24: FALSO | V24: Se descarta
A25: 3628 | B25: 50 | C25: 103 | D25: 14 | E25: 43591 | F25: 5251 | G25: 7996 | H25: 7177 | J25: =+(((G25-F25)-(H25-F25))/(H25-F25))*100 | P25: =+(((H25-F25)/1000)*1000)/10 | R25: FALSO | S25: FALSO | V25: Se descarta
A26: 4295 | B26: 1 | C26: 103 | D26: 16 | E26: 43607 | F26: 5301 | G26: 7689 | H26: 7126 | I26: 2 | J26: =+(((G26-F26)-(H26-F26))/(H26-F26))*100 | L26: =AVERAGE(J26:J27) | M26: =_xlfn.STDEV.S(J26,J27) | P26: =+(((H26-F26)/1000)*1000)/10 | Q26: =AVERAGE(P26:P27) | R26: FALSO | S26: FALSO | V26: Se descarta
A27: 4296 | B27: 2 | C27: 103 | D27: 16 | E27: 43607 | F27: 5190 | G27: 7602 | H27: 7029 | J27: =+(((G27-F27)-(H27-F27))/(H27-F27))*100 | P27: =+(((H27-F27)/1000)*1000)/10 | R27: FALSO | S27: FALSO | V27: Se descarta
A28: 4941 | B28: 1 | C28: 103 | D28: 18 | E28: 43626 | F28: 5301 | G28: 7918 | H28: 7461 | I28: 13 | J28: =+(((G28-F28)-(H28-F28))/(H28-F28))*100 | L28: =AVERAGE(J28:J29) | M28: =_xlfn.STDEV.S(J28,J29) | P28: =+(((H28-F28)/1000)*1000)/10 | Q28: =AVERAGE(P28:P29) | R28: FALSO | S28: FALSO | V28: Se descarta
A29: 4942 | B29: 2 | C29: 103 | D29: 18 | E29: 43626 | F29: 5190 | G29: 7592 | H29: 7159 | J29: =+(((G29-F29)-(H29-F29))/(H29-F29))*100 | P29: =+(((H29-F29)/1000)*1000)/10 | R29: FALSO | S29: FALSO | V29: Se descarta
A30: 5557 | B30: 1 | C30: 103 | D30: 21 | E30: 43657 | F30: 5301 | G30: 7923 | H30: 7497 | I30: 13 | J30: =+(((G30-F30)-(H30-F30))/(H30-F30))*100 | L30: =AVERAGE(J30:J31) | M30: =_xlfn.STDEV.S(J30,J31) | P30: =+(((H30-F30)/1000)*1000)/10 | Q30: =AVERAGE(P30:P31) | R30: FALSO | S30: FALSO | V30: Se descarta
A31: 5558 | B31: 2 | C31: 103 | D31: 21 | E31: 43657 | F31: 5190 | G31: 7912 | H31: 7456 | J31: =+(((G31-F31)-(H31-F31))/(H31-F31))*100 | P31: =+(((H31-F31)/1000)*1000)/10 | R31: FALSO | S31: FALSO | V31: Se descarta
A32: 5759 | B32: 3 | C32: 103 | D32: 22 | E32: 43685 | F32: 5258 | G32: 7291 | H32: 7007 | I32: 13 | J32: =+(((G32-F32)-(H32-F32))/(H32-F32))*100 | L32: =AVERAGE(J32:J33) | M32: =_xlfn.STDEV.S(J32,J33) | P32: =+(((H32-F32)/1000)*1000)/10 | Q32: =AVERAGE(P32:P33) | R32: FALSO | S32: FALSO | V32: Se descarta
A33: 5760 | B33: 3 | C33: 103 | D33: 22 | E33: 43685 | F33: 5258 | G33: 7368 | H33: 7077 | J33: =+(((G33-F33)-(H33-F33))/(H33-F33))*100 | P33: =+(((H33-F33)/1000)*1000)/10 | R33: FALSO | S33: FALSO | V33: Se descarta
A34: 3249 | B34: 5 | C34: 104 | D34: 13 | E34: 43587 | F34: 5236 | G34: 7239 | H34: 6821 | I34: 1 | J34: =+(((G34-F34)-(H34-F34))/(H34-F34))*100 | K34: MF | L34: =AVERAGE(J34:J35) | M34: =_xlfn.STDEV.S(J34,J35) | N34: 1 | P34: =+(((H34-F34)/1000)*1000)/10 | Q34: =AVERAGE(P34:P35) | R34: FALSO | S34: FALSO | V34: Se descarta
A35: 3250 | B35: 6 | C35: 104 | D35: 13 | E35: 43587 | F35: 5259 | G35: 7188 | H35: 6786 | J35: =+(((G35-F35)-(H35-F35))/(H35-F35))*100 | P35: =+(((H35-F35)/1000)*1000)/10 | R35: FALSO | S35: FALSO | V35: Se descarta
A36: 3975 | B36: 5 | C36: 104 | D36: 15 | E36: 43599 | F36: 5236 | G36: 7120 | H36: 6744 | J36: =+(((G36-F36)-(H36-F36))/(H36-F36))*100 | L36: =AVERAGE(J36:J37) | M36: =_xlfn.STDEV.S(J36,J37) | P36: =+(((H36-F36)/1000)*1000)/10 | Q36: =AVERAGE(P36:P37) | R36: FALSO | S36: FALSO | V36: Se descarta
A37: 3976 | B37: 6 | C37: 104 | D37: 15 | E37: 43599 | F37: 5259 | G37: 7153 | H37: 6787 | J37: =+(((G37-F37)-(H37-F37))/(H37-F37))*100 | P37: =+(((H37-F37)/1000)*1000)/10 | R37: FALSO | S37: FALSO | V37: Se descarta
A38: 4621 | B38: 5 | C38: 104 | D38: 17 | E38: 43619 | F38: 5236 | G38: 7185 | H38: 6842 | J38: =+(((G38-F38)-(H38-F38))/(H38-F38))*100 | L38: =AVERAGE(J38:J39) | M38: =_xlfn.STDEV.S(J38,J39) | P38: =+(((H38-F38)/1000)*1000)/10 | Q38: =AVERAGE(P38:P39) | R38: FALSO | S38: FALSO | V38: Se descarta
A39: 4622 | B39: 6 | C39: 104 | D39: 17 | E39: 43619 | F39: 5259 | G39: 7206 | H39: 6864 | J39: =+(((G39-F39)-(H39-F39))/(H39-F39))*100 | P39: =+(((H39-F39)/1000)*1000)/10 | R39: FALSO | S39: FALSO | V39: Se descarta
A40: 5267 | B40: 5 | C40: 104 | D40: 19 | E40: 43637 | F40: 5236 | G40: 7128 | H40: 6764 | I40: 10 | J40: =+(((G40-F40)-(H40-F40))/(H40-F40))*100 | L40: =AVERAGE(J40:J41) | M40: =_xlfn.STDEV.S(J40,J41) | P40: =+(((H40-F40)/1000)*1000)/10 | Q40: =AVERAGE(P40:P41) | R40: FALSO | S40: FALSO | V40: Se descarta
...

Sheet ENS TARDIO 201819
A1: PLOT | B1: BLOC | C1: IBLK | D1: ENTRY | E1: ORIGEN | F1: PEDIGREE | G1: PTAS | H1: VT | I1: GDU_VT | J1: R1 | K1: GDU_R1 | L1: ASI | M1: GDU_ASI | N1: MF | O1: MC | P1: TSG | Q1: Tallo | R1: Roya | S1: MRCV | T1: TIZON | U1: BACT | V1: SG | W1: OBSERV | X1: Decisión
A2: 101 | B2: 1 | C2: 1 | D2: 60 | E2: 17.2804 | F2: [BSGA] 04.4060-1.1.1.1.1.#.# | H2: 43521 | I2: 1182.6 | J2: 43523 | K2: 1198.75 | L2: 16.15 | M2: ='ENS TARDIO 201819'!$K2-'ENS TARDIO 201819'!$I2 | N2: 43595 | O2: 43693 | P2: 0.193 | X2: Plot Válido
A3: 102 | B3: 1 | C3: 1 | D3: 85 | E3: 17.2860 | F3: [BS29 ] 04.696-1.1.1.1.1.# | H3: 43521 | I3: 1182.6 | J3: 43521 | K3: 1182.6 | L3: 0 | M3: ='ENS TARDIO 201819'!$K3-'ENS TARDIO 201819'!$I3 | N3: 43615 | O3: 43701 | P3: 0.275
A4: 103 | B4: 1 | C4: 1 | D4: 129 | E4: 17.2948//BEBA | F4: LP 611 | H4: 43523 | I4: 1198.75 | J4: 43525 | K4: 1226.25 | L4: 27.5 | M4: ='ENS TARDIO 201819'!$K4-'ENS TARDIO 201819'!$I4
A5: 104 | B5: 1 | C5: 1 | D5: 64 | E5: 17.2812 | F5: [BSGA] 04.4092-1.1.1.1.1.#.# | H5: 43522 | I5: 1188.8 | J5: 43523 | K5: 1198.75 | L5: 9.95 | M5: ='ENS TARDIO 201819'!$K5-'ENS TARDIO 201819'!$I5 | P5: 0.107
A6: 105 | B6: 1 | C6: 1 | D6: 95 | E6: 17.2880 | F6: [FESTIVAL] 04.785-1.1.1.1.1.# | H6: 43524 | I6: 1210.9 | J6: 43524 | K6: 1210.9 | L6: 0 | M6: ='ENS TARDIO 201819'!$K6-'ENS TARDIO 201819'!$I6 | N6: 43598 | O6: 43692 | P6: 0.264
A7: 106 | B7: 1 | C7: 1 | D7: 134 | E7: 17.2958 | F7: LP 153 | H7: 43520 | I7: 1173.8 | J7: 43519 | K7: 1161.75 | L7: -12.05 | M7: ='ENS TARDIO 201819'!$K7-'ENS TARDIO 201819'!$I7 | N7: 43589 | O7: 43700 | P7: 0.16
A8: 107 | B8: 1 | C8: 1 | D8: 16 | E8: 17.2586 | F8: bulk 04.1973-46-1@-1#1 | H8: 43527 | I8: 1249.9 | J8: 43527 | K8: 1249.9 | L8: 0 | M8: ='ENS TARDIO 201819'!$K8-'ENS TARDIO 201819'!$I8
A9: 108 | B9: 1 | C9: 1 | D9: 108 | E9: 17.2906 | F9: LP 212 | H9: 43523 | I9: 1198.75 | J9: 43522 | K9: 1188.8 | L9: -9.95 | M9: ='ENS TARDIO 201819'!$K9-'ENS TARDIO 201819'!$I9 | N9: 43589 | O9: 43689 | P9: 0.174
A10: 109 | B10: 1 | C10: 1 | D10: 145 | E10: 17.2978 | F10: LP 916 | H10: 43527 | I10: 1249.9 | J10: 43527 | K10: 1249.9 | L10: 0 | M10: ='ENS TARDIO 201819'!$K10-'ENS TARDIO 201819'!$I10
A11: 110 | B11: 1 | C11: 1 | D11: 57 | E11: 17.2798//15.253 | F11: LP581xLP562-1-50-1-1 | M11: ='ENS TARDIO 201819'!$K11-'ENS TARDIO 201819'!$I11
A12: 111 | B12: 1 | C12: 1 | D12: 123 | E12: 17.2936 | F12: LP 116 | H12: 43524 | I12: 1210.9 | J12: 43525 | K12: 1226.25 | L12: 15.35 | M12: ='ENS TARDIO 201819'!$K12-'ENS TARDIO 201819'!$I12
A13: 112 | B13: 1 | C13: 1 | D13: 29 | E13: 17.2614 | F13: 99.5905-1-1-1-1-1#1-1#1#1#1-1 | H13: 43517 | I13: 1128.65 | J13: 43517 | K13: 1128.65 | L13: 0 | M13: ='ENS TARDIO 201819'!$K13-'ENS TARDIO 201819'!$I13
A14: 113 | B14: 1 | C14: 2 | D14: 165 | E14: 17.3018 | F14: P21 | H14: 43521 | I14: 1182.6 | J14: 43524 | K14: 1210.9 | L14: 28.3 | M14: ='ENS TARDIO 201819'!$K14-'ENS TARDIO 201819'!$I14 | N14: 43513 | O14: 43692 | P14: 0.228
A15: 114 | B15: 1 | C15: 2 | D15: 150 | E15: 17.2988 | F15: LP 178 | H15: 43520 | I15: 1173.8 | J15: 43523 | K15: 1198.75 | L15: 24.95 | M15: ='ENS TARDIO 201819'!$K15-'ENS TARDIO 201819'!$I15
A16: 115 | B16: 1 | C16: 2 | D16: 139 | E16: 17.2966 | F16: LP 2 | H16: 43521 | I16: 1182.6 | J16: 43522 | K16: 1188.8 | L16: 6.2 | M16: ='ENS TARDIO 201819'!$K16-'ENS TARDIO 201819'!$I16
A17: 116 | B17: 1 | C17: 2 | D17: 147 | E17: 17.2982 | F17: LP 915 | H17: 43525 | I17: 1226.25 | J17: 43527 | K17: 1249.9 | L17: 23.65 | M17: ='ENS TARDIO 201819'!$K17-'ENS TARDIO 201819'!$I17
A18: 117 | B18: 1 | C18: 2 | D18: 24 | E18: 17.2604 | F18: bulk 04.1973-143-1-1-1#1#1 | H18: 43525 | I18: 1226.25 | J18: 43525 | K18: 1226.25 | L18: 0 | M18: ='ENS TARDIO 201819'!$K18-'ENS TARDIO 201819'!$I18
A19: 118 | B19: 1 | C19: 2 | D19: 4 | E19: 15.9//SYN7 | F19: BKBS13idprov901947-1-75 -1-1@-1#1 | H19: 43522 | I19: 1188.8 | J19: 43525 | K19: 1226.25 | L19: 37.45 | M19: ='ENS TARDIO 201819'!$K19-'ENS TARDIO 201819'!$I19
A20: 119 | B20: 1 | C20: 2 | D20: 6 | E20: 17.2566 | F20: BKBS13idprov901947-1-113 -1-1-1-1#1 | H20: 43526 | I20: 1238 | J20: 43528 | K20: 1262.15 | L20: 24.15 | M20: ='ENS TARDIO 201819'!$K20-'ENS TARDIO 201819'!$I20
A21: 120 | B21: 1 | C21: 2 | D21: 53 | E21: 17.2694 | F21: (7310x7266)-1-40 | H21: 43526 | I21: 1238 | J21: 43528 | K21: 1262.15 | L21: 24.15 | M21: ='ENS TARDIO 201819'!$K21-'ENS TARDIO 201819'!$I21
A22: 121 | B22: 1 | C22: 2 | D22: 50 | E22: 17.2668 | F22: (7310x7266)-1-15 | H22: 43522 | I22: 1188.8 | J22: 43522 | K22: 1188.8 | L22: 0 | M22: ='ENS TARDIO 201819'!$K22-'ENS TARDIO 201819'!$I22
A23: 122 | B23: 1 | C23: 2 | D23: 141 | E23: 17.2970 | F23: LPB2 | H23: 43526 | I23: 1238 | J23: 43527 | K23: 1249.9 | L23: 11.9 | M23: ='ENS TARDIO 201819'!$K23-'ENS TARDIO 201819'!$I23
A24: 123 | B24: 1 | C24: 2 | D24: 168 | E24: 17.1536 | F24: L2200 | H24: 43514 | I24: 1069.6 | J24: 43514 | K24: 1069.6 | L24: 0 | M24: ='ENS TARDIO 201819'!$K24-'ENS TARDIO 201819'!$I24
A25: 124 | B25: 1 | C25: 2 | D25: 96 | E25: 17.2882 | F25: [PIO3162] 04.629-1.1.1.1.1.# // LP03001 | H25: 43523 | I25: 1198.75 | J25: 43522 | K25: 1188.8 | L25: -9.95 | M25: ='ENS TARDIO 201819'!$K25-'ENS TARDIO 201819'!$I25
A26: 125 | B26: 1 | C26: 3 | D26: 47 | E26: 17.2654 | F26: (7310x7266)-1-1 | H26: 43525 | I26: 1226.25 | J26: 43525 | K26: 1226.25 | L26: 0 | M26: ='ENS TARDIO 201819'!$K26-'ENS TARDIO 201819'!$I26
... A56: 155 | B56: 1 | C56: 5 | D56: 86 | E56: 17.2862//15.331 | F56: [BS29 ] 04.701-1.1.1.1.1.# | H56: 43522 | I56: 1188.8 | J56: 43521 | K56: 1182.6 | L56: -6.2 | M56: ='ENS TARDIO 201819'!$K56-'ENS TARDIO 201819'!$I56
A57: 156 | B57: 1 | C57: 5 | D57: 35 | E57: 17.2630 | F57: (95.6277/6278)F2-bk25eS1-9-1-1-1-1-1##1#1-1 | M57: ='ENS TARDIO 201819'!$K57-'ENS TARDIO 201819'!$I57
A58: 157 | B58: 1 | C58: 5 | D58: 82 | E58: 13.2212//12.2977 | F58: [AX889] 04.719-1.1.1.1.1.# | H58: 43532 | I58: 1316.95 | J58: 43532 | K58: 1316.95 | L58: 0 | M58: ='ENS TARDIO 201819'!$K58-'ENS TARDIO 201819'!$I58
A59: 158 | B59: 1 | C59: 5 | D59: 125 | E59: 17.2940 | F59: LP 122 | H59: 43520 | I59: 1173.8 | J59: 43521 | K59: 1182.6 | L59: 8.8 | M59: ='ENS TARDIO 201819'!$K59-'ENS TARDIO 201819'!$I59
A60: 159 | B60: 1 | C60: 5 | D60: 164 | E60: 17.3016 | F60: P465 | H60: 43520 | I60: 1173.8 | J60: 43522 | K60: 1188.8 | L60: 15 | M60: ='ENS TARDIO 201819'!$K60-'ENS TARDIO 201819'!$I60
A61: 160 | B61: 1 | C61: 5 | D61: 69 | E61: 17.2822 | F61: [SynSDSP] 04.3990-1.1.1.1.1.1.# | H61: 43519 | I61: 1161.75 | J61: 43522 | K61: 1188.8 | L61: 27.05 | M61: ='ENS TARDIO 201819'!$K61-'ENS TARDIO 201819'!$I61
A62: 161 | B62: 1 | C62: 6 | D62: 9 | E62: 17.2572 | F62: BKBS13idprov901947-1-132 -1-1-1-1#1 | H62: 43520 | I62: 1173.8 | J62: 43522 | K62: 1188.8 | L62: 15 | M62: ='ENS TARDIO 201819'!$K62-'ENS TARDIO 201819'!$I62
A63: 162 | B63: 1 | C63: 6 | D63: 87 | E63: 17.2864 | F63: [CDP] 04.649-1.1.1.1.1.# | H63: 43519 | I63: 1161.75 | J63: 43523 | K63: 1198.75 | L63: 37 | M63: ='ENS TARDIO 201819'!$K63-'ENS TARDIO 201819'!$I63
A64: 163 | B64: 1 | C64: 6 | D64: 137 | E64: 17.2962 | F64: LP 256-R | H64: 43520 | I64: 1173.8 | J64: 43521 | K64: 1182.6 | L64: 8.8 | M64: ='ENS TARDIO 201819'!$K64-'ENS TARDIO 201819'!$I64
A65: 164 | B65: 1 | C65: 6 | D65: 65 | E65: 17.2814 | F65: [BSGA] 04.4114-1.1.1.1.1.#.# | H65: 43520 | I65: 1173.8 | J65: 43522 | K65: 1188.8 | L65: 15 | M65: ='ENS TARDIO 201819'!$K65-'ENS TARDIO 201819'!$I65
A66: 165 | B66: 1 | C66: 6 | D66: 2 | E66: 17.2558 | F66: BKBS13idprov901947-1-30 -1-1@-1#1 | H66: 43519 | I66: 1161.75 | J66: 43520 | K66: 1173.8 | L66: 12.05 | M66: ='ENS TARDIO 201819'!$K66-'ENS TARDIO 201819'!$I66
A67: 166 | B67: 1 | C67: 6 | D67: 68 | E67: 17.2820//NN15.667 | F67: [BSGA] 04.4165-1.1.1.1.1.#.# | H67: 43525 | I67: 1226.25 | J67: 43525 | K67: 1226.25 | L67: 0 | M67: ='ENS TARDIO 201819'!$K67-'ENS TARDIO 201819'!$I67
A68: 167 | B68: 1 | C68: 6 | D68: 114 | E68: 17.2918 | F68: LP 168 | H68: 43513 | I68: 1051.95 | J68: 43514 | K68: 1069.6 | L68: 17.65 | M68: ='ENS TARDIO 201819'!$K68-'ENS TARDIO 201819'!$I68
A69: 168 | B69: 1 | C69: 6 | D69: 49 | E69: 17.2662 | F69: (7310x7266)-1-11 | H69: 43522 | I69: 1188.8 | J69: 43527 | K69: 1249.9 | L69: 61.1 | M69: ='ENS TARDIO 201819'!$K69-'ENS TARDIO 201819'!$I69
...

Sheet DATOS HUM
A1: Nº Muestra | B1: Lata | C1: Plot | D1: Muestreo | E1: Fecha | F1: Peso Tara | G1: Peso Húmedo | H1: Peso Seco | I1: Chala | J1: HUM
A2: 1 | B2: 1 | C2: 102 | D2: 1 | E2: 43514 | F2: 5301 | G2: 7194 | H2: 6963 | I2: 12 | J2: =+(((G2-F2)-(H2-F2))/(H2-F2))*100
A3: 2 | B3: 2 | C3: 102 | D3: 1 | E3: 43514 | F3: 5190 | G3: 6963 | H3: 6746 | J3: =+(((G3-F3)-(H3-F3))/(H3-F3))*100
A4: 3 | B4: 3 | C4: 104 | D4: 1 | E4: 43514 | F4: 5258 | G4: 8211 | H4: 7784 | I4: 8 | J4: =+(((G4-F4)-(H4-F4))/(H4-F4))*100
A5: 4 | B5: 4 | C5: 104 | D5: 1 | E5: 43514 | F5: 5259 | G5: 8193 | H5: 7767 | J5: =+(((G5-F5)-(H5-F5))/(H5-F5))*100
A6: 5 | B6: 5 | C6: 107 | D6: 1 | E6: 43514 | F6: 5236 | G6: 7923 | H6: 7474 | I6: 10 | J6: =+(((G6-F6)-(H6-F6))/(H6-F6))*100
A7: 6 | B7: 6 | C7: 107 | D7: 1 | E7: 43514 | F7: 5259 | G7: 7658 | H7: 7288 | J7: =+(((G7-F7)-(H7-F7))/(H7-F7))*100
A8: 7 | B8: 7 | C8: 108 | D8: 1 | E8: 43514 | F8: 5232 | G8: 8351 | H8: 7792 | I8: 12 | J8: =+(((G8-F8)-(H8-F8))/(H8-F8))*100
A9: 8 | B9: 8 | C9: 108 | D9: 1 | E9: 43514 | F9: 5221 | G9: 8221 | H9: 7698 | J9: =+(((G9-F9)-(H9-F9))/(H9-F9))*100
A10: 9 | B10: 9 | C10: 109 | D10: 1 | E10: 43514 | F10: 5188 | G10: 6829 | H10: 6580 | I10: 9 | J10: =+(((G10-F10)-(H10-F10))/(H10-F10))*100
A11: 10 | B11: 10 | C11: 109 | D11: 1 | E11: 43514 | F11: 5232 | G11: 6711 | H11: 6516 | J11: =+(((G11-F11)-(H11-F11))/(H11-F11))*100
A12: 11 | B12: 11 | C12: 112 | D12: 1 | E12: 43514 | F12: 5213 | G12: 9019 | H12: 7675 | I12: 9 | J12: =+(((G12-F12)-(H12-F12))/(H12-F12))*100
A13: 12 | B13: 12 | C13: 112 | D13: 1 | E13: 43514 | F13: 5232 | G13: 9109 | H13: 7776 | J13: =+(((G13-F13)-(H13-F13))/(H13-F13))*100
A14: 13 | B14: 13 | C14: 115 | D14: 1 | E14: 43514 | F14: 5314 | G14: 8051 | H14: 7258 | I14: 10 | J14: =+(((G14-F14)-(H14-F14))/(H14-F14))*100
A15: 14 | B15: 14 | C15: 115 | D15: 1 | E15: 43514 | F15: 5249 | G15: 8111 | H15: 7324 | J15: =+(((G15-F15)-(H15-F15))/(H15-F15))*100
A16: 15 | B16: 15 | C16: 116 | D16: 1 | E16: 43514 | F16: 5231 | G16: 8339 | H16: 7545 | I16: 11 | J16: =+(((G16-F16)-(H16-F16))/(H16-F16))*100
A17: 16 | B17: 16 | C17: 116 | D17: 1 | E17: 43514 | F17: 5280 | G17: 8341 | H17: 7572 | J17: =+(((G17-F17)-(H17-F17))/(H17-F17))*100
A18: 17 | B18: 17 | C18: 120 | D18: 1 | E18: 43514 | F18: 5275 | G18: 8212 | H18: 7441 | I18: 10 | J18: =+(((G18-F18)-(H18-F18))/(H18-F18))*100
A19: 18 | B19: 18 | C19: 120 | D19: 1 | E19: 43514 | F19: 5205 | G19: 8221 | H19: 7438 | J19: =+(((G19-F19)-(H19-F19))/(H19-F19))*100
A20: 19 | B20: 19 | C20: 121 | D20: 1 | E20: 43514 | F20: 5229 | G20: 8913 | H20: 7799 | I20: 9 | J20: =+(((G20-F20)-(H20-F20))/(H20-F20))*100
A21: 20 | B21: 20 | C21: 121 | D21: 1 | E21: 43514 | F21: 5190 | G21: 8705 | H21: 7631 | J21: =+(((G21-F21)-(H21-F21))/(H21-F21))*100
A22: 21 | B22: 21 | C22: 123 | D22: 1 | E22: 43514 | F22: 5224 | G22: 8860 | H22: 7893 | I22: 10 | J22: =+(((G22-F22)-(H22-F22))/(H22-F22))*100
A23: 22 | B23: 22 | C23: 123 | D23: 1 | E23: 43514 | F23: 5276 | G23: 8907 | H23: 7929 | J23: =+(((G23-F23)-(H23-F23))/(H23-F23))*100
A24: 23 | B24: 23 | C24: 124 | D24: 1 | E24: 43514 | F24: 5261 | G24: 8267 | H24: 7387 | I24: 11 | J24: =+(((G24-F24)-(H24-F24))/(H24-F24))*100
A25: 24 | B25: 24 | C25: 124 | D25: 1 | E25: 43514 | F25: 5196 | G25: 8163 | H25: 7310 | J25: =+(((G25-F25)-(H25-F25))/(H25-F25))*100
A26: 25 | B26: 25 | C26: 125 | D26: 1 | E26: 43514 | F26: 5238 | G26: 8669 | H26: 7797 | I26: 8 | J26: =+(((G26-F26)-(H26-F26))/(H26-F26))*100
A27: 26 | B27: 26 | C27: 125 | D27: 1 | E27: 43514 | F27: 5207 | G27: 8424 | H27: 7611 | J27: =+(((G27-F27)-(H27-F27))/(H27-F27))*100
A28: 27 | B28: 27 | C28: 126 | D28: 1 | E28: 43514 | F28: 5236 | J28: =+(((G28-F28)-(H28-F28))/(H28-F28))*100
A29: 28 | B29: 28 | C29: 126 | D29: 1 | E29: 43514 | F29: 5216 | J29: =+(((G29-F29)-(H29-F29))/(H29-F29))*100
A30: 29 | B30: 29 | C30: 128 | D30: 1 | E30: 43514 | F30: 5292 | G30: 7352 | H30: 6817 | I30: 9 | J30: =+(((G30-F30)-(H30-F30))/(H30-F30))*100
A31: 30 | B31: 30 | C31: 128 | D31: 1 | E31: 43514 | F31: 5244 | G31: 7069 | H31: 6595 | J31: =+(((G31-F31)-(H31-F31))/(H31-F31))*100
A32: 31 | B32: 31 | C32: 129 | D32: 1 | E32: 43514 | F32: 5227 | G32: 6458 | H32: 6110 | I32: 9 | J32: =+(((G32-F32)-(H32-F32))/(H32-F32))*100
A33: 32 | B33: 32 | C33: 129 | D33: 1 | E33: 43514 | F33: 5214 | G33: 6595 | H33: 6081 | J33: =+(((G33-F33)-(H33-F33))/(H33-F33))*100
A34: 33 | B34: 33 | C34: 131 | D34: 1 | E34: 43514 | F34: 5203 | G34: 8159 | H34: 7298 | I34: 11 | J34: =+(((G34-F34)-(H34-F34))/(H34-F34))*100
A35: 34 | B35: 34 | C35: 131 | D35: 1 | E35: 43514 | F35: 5191 | G35: 7914 | H35: 7092 | J35: =+(((G35-F35)-(H35-F35))/(H35-F35))*100
A36: 35 | B36: 35 | C36: 133 | D36: 1 | E36: 43514 | F36: 5280 | G36: 8143 | H36: 7504 | I36: 9 | J36: =+(((G36-F36)-(H36-F36))/(H36-F36))*100
A37: 36 | B37: 36 | C37: 133 | D37: 1 | E37: 43514 | F37: 5219 | G37: 8231 | H37: 7542 | J37: =+(((G37-F37)-(H37-F37))/(H37-F37))*100
A38: 37 | B38: 37 | C38: 134 | D38: 1 | E38: 43514 | F38: 5225 | G38: 9388 | H38: 8214 | I38: 10 | J38: =+(((G38-F38)-(H38-F38))/(H38-F38))*100
A39: 38 | B39: 38 | C39: 134 | D39: 1 | E39: 43514 | F39: 5241 | G39: 9597 | H39: 8355 | J39: =+(((G39-F39)-(H39-F39))/(H39-F39))*100
A40: 39 | B40: 39 | C40: 139 | D40: 1 | E40: 43514 | F40: 5245 | G40: 7854 | H40: 7213 | I40: 10 | J40: =+(((G40-F40)-(H40-F40))/(H40-F40))*100
...

Sheet HUM TARD¿¿
A1: Nº Muestra | B1: Lata | C1: Plot | D1: dumi | E1: Columna1 | F1: Columna2 | G1: Muestreo | H1: Fecha | I1: Peso Tara | J1: Peso Húmedo | K1: Peso Seco | L1: Chala | M1: HUM | N1: MF | O1: HM X | P1: DE | Q1: Columna3 | R1: TSG | S1: Peso Seco Mil | T1: P_S_Mil
A2: 3245 | B2: 1 | C2: T101 | D2: 1 | G2: 13 | H2: 43587 | I2: 5301 | J2: 8480 | K2: 7635 | L2: 1 | M2: =+(((J2-I2)-(K2-I2))/(K2-I2))*100 | N2: 1/4 | O2: =AVERAGE(M2:M3) | P2: =_xlfn.STDEV.S(M2,M3) | Q2: 1 | S2: =+(((K2-I2)/1000)*1000)/10 | T2: =AVERAGE(S2:S3)
A3: 3246 | B3: 2 | C3: T101 | D3: 2 | G3: 13 | H3: 43587 | I3: 5190 | J3: 8093 | K3: 7277 | M3: =+(((J3-I3)-(K3-I3))/(K3-I3))*100 | S3: =+(((K3-I3)/1000)*1000)/10
A4: 3971 | B4: 1 | C4: T101 | D4: 3 | G4: 15 | H4: 43599 | I4: 5301 | J4: 9609 | K4: 8132 | M4: =+(((J4-I4)-(K4-I4))/(K4-I4))*100 | N4: 10/5 | O4: =AVERAGE(M4:M5) | P4: =_xlfn.STDEV.S(M4,M5) | S4: =+(((K4-I4)/1000)*1000)/10 | T4: =AVERAGE(S4:S5)
A5: 3972 | B5: 2 | C5: T101 | D5: 4 | G5: 15 | H5: 43599 | I5: 5190 | J5: 8993 | K5: 7675 | M5: =+(((J5-I5)-(K5-I5))/(K5-I5))*100 | S5: =+(((K5-I5)/1000)*1000)/10
A6: 4617 | B6: 1 | C6: T101 | D6: 5 | G6: 17 | H6: 43619 | I6: 5301 | J6: 6901 | K6: 6651 | M6: =+(((J6-I6)-(K6-I6))/(K6-I6))*100 | O6: =AVERAGE(M6:M7) | P6: =_xlfn.STDEV.S(M6,M7) | S6: =+(((K6-I6)/1000)*1000)/10 | T6: =AVERAGE(S6:S7)
A7: 4618 | B7: 2 | C7: T101 | D7: 6 | G7: 17 | H7: 43619 | I7: 5190 | J7: 6731 | K7: 6495 | M7: =+(((J7-I7)-(K7-I7))/(K7-I7))*100 | S7: =+(((K7-I7)/1000)*1000)/10
A8: 5263 | B8: 1 | C8: T101 | D8: 7 | G8: 19 | H8: 43637 | I8: 5301 | J8: 8381 | K8: 7759 | L8: 9/10 | M8: =+(((J8-I8)-(K8-I8))/(K8-I8))*100 | O8: =AVERAGE(M8:M9) | P8: =_xlfn.STDEV.S(M8,M9) | S8: =+(((K8-I8)/1000)*1000)/10 | T8: =AVERAGE(S8:S9)
A9: 5264 | B9: 2 | C9: T101 | D9: 8 | G9: 19 | H9: 43637 | I9: 5190 | J9: 8166 | K9: 7567 | M9: =+(((J9-I9)-(K9-I9))/(K9-I9))*100 | S9: =+(((K9-I9)/1000)*1000)/10
A10: 5509 | B10: 1 | C10: T101 | D10: 9 | G10: 20 | H10: 43649 | I10: 5301 | J10: 8263 | K10: 7715 | L10: 9 | M10: =+(((J10-I10)-(K10-I10))/(K10-I10))*100 | O10: =AVERAGE(M10:M11) | P10: =_xlfn.STDEV.S(M10,M11) | S10: =+(((K10-I10)/1000)*1000)/10 | T10: =AVERAGE(S10:S11)
A11: 5510 | B11: 2 | C11: T101 | D11: 10 | G11: 20 | H11: 43649 | I11: 5190 | J11: 8070 | K11: 7542 | M11: =+(((J11-I11)-(K11-I11))/(K11-I11))*100 | S11: =+(((K11-I11)/1000)*1000)/10
A12: 5755 | B12: 1 | C12: T101 | D12: 11 | G12: 22 | H12: 43685 | I12: 5301 | J12: 7766 | K12: 7421 | L12: 6 | M12: =+(((J12-I12)-(K12-I12))/(K12-I12))*100 | O12: =AVERAGE(M12:M13) | P12: =_xlfn.STDEV.S(M12,M13) | Q12: =(O10-O12)/36 | R12: =(O8-O12)/48 | S12: =+(((K12-I12)/1000)*1000)/10 | T12: =AVERAGE(S12:S13)
A13: 5756 | B13: 1 | C13: T101 | D13: 12 | G13: 22 | H13: 43685 | I13: 5301 | J13: 7801 | K13: 7462 | M13: =+(((J13-I13)-(K13-I13))/(K13-I13))*100 | S13: =+(((K13-I13)/1000)*1000)/10
A14: 3247 | B14: 3 | C14: T102 | D14: 1 | G14: 13 | H14: 43587 | I14: 5258 | J14: 9293 | K14: 7999 | L14: 1 | M14: =+(((J14-I14)-(K14-I14))/(K14-I14))*100 | N14: 1/2 | O14: =AVERAGE(M14:M15) | P14: =_xlfn.STDEV.S(M14,M15) | Q14: 1 | S14: =+(((K14-I14)/1000)*1000)/10 | T14: =AVERAGE(S14:S15)
A15: 3248 | B15: 4 | C15: T102 | D15: 2 | G15: 13 | H15: 43587 | I15: 5259 | J15: 9138 | K15: 7924 | M15: =+(((J15-I15)-(K15-I15))/(K15-I15))*100 | S15: =+(((K15-I15)/1000)*1000)/10
A16: 3973 | B16: 3 | C16: T102 | D16: 3 | G16: 15 | H16: 43599 | I16: 5258 | J16: 8236 | K16: 7373 | M16: =+(((J16-I16)-(K16-I16))/(K16-I16))*100 | N16: MF* | O16: =AVERAGE(M16:M17) | P16: =_xlfn.STDEV.S(M16,M17) | S16: =+(((K16-I16)/1000)*1000)/10 | T16: =AVERAGE(S16:S17)
A17: 3974 | B17: 4 | C17: T102 | D17: 4 | G17: 15 | H17: 43599 | I17: 5259 | J17: 8423 | K17: 7537 | M17: =+(((J17-I17)-(K17-I17))/(K17-I17))*100 | S17: =+(((K17-I17)/1000)*1000)/10
A18: 4619 | B18: 3 | C18: T102 | D18: 5 | G18: 17 | H18: 43619 | I18: 5258 | J18: 7811 | K18: 7349 | M18: =+(((J18-I18)-(K18-I18))/(K18-I18))*100 | O18: =AVERAGE(M18:M19) | P18: =_xlfn.STDEV.S(M18,M19) | S18: =+(((K18-I18)/1000)*1000)/10 | T18: =AVERAGE(S18:S19)
A19: 4620 | B19: 4 | C19: T102 | D19: 6 | G19: 17 | H19: 43619 | I19: 5259 | J19: 7715 | K19: 7282 | M19: =+(((J19-I19)-(K19-I19))/(K19-I19))*100 | S19: =+(((K19-I19)/1000)*1000)/10
A20: 5265 | B20: 3 | C20: T102 | D20: 7 | G20: 19 | H20: 43637 | I20: 5258 | J20: 9414 | K20: 8355 | L20: 6 | M20: =+(((J20-I20)-(K20-I20))/(K20-I20))*100 | O20: =AVERAGE(M20:M21) | P20: =_xlfn.STDEV.S(M20,M21) | S20: =+(((K20-I20)/1000)*1000)/10 | T20: =AVERAGE(S20:S21)
A21: 5266 | B21: 4 | C21: T102 | D21: 8 | G21: 19 | H21: 43637 | I21: 5259 | J21: 9455 | K21: 8361 | M21: =+(((J21-I21)-(K21-I21))/(K21-I21))*100 | S21: =+(((K21-I21)/1000)*1000)/10
A22: 5757 | B22: 2 | C22: T102 | D22: 9 | G22: 22 | H22: 43685 | I22: 5190 | J22: 7725 | K22: 7370 | L22: 6 | M22: =+(((J22-I22)-(K22-I22))/(K22-I22))*100 | O22: =AVERAGE(M22:M23) | P22: =_xlfn.STDEV.S(M22,M23) | Q22: =(O18-O22)/66 | R22: =(O16-O22)/86 | S22: =+(((K22-I22)/1000)*1000)/10 | T22: =AVERAGE(S22:S23)
A23: 5758 | B23: 2 | C23: T102 | D23: 10 | G23: 22 | H23: 43685 | I23: 5190 | J23: 7597 | K23: 7266 | M23: =+(((J23-I23)-(K23-I23))/(K23-I23))*100 | S23: =+(((K23-I23)/1000)*1000)/10
A24: 3627 | B24: 49 | C24: T103 | D24: 1 | G24: 14 | H24: 43591 | I24: 5203 | J24: 7980 | K24: 7170 | L24: 2 | M24: =+(((J24-I24)-(K24-I24))/(K24-I24))*100 | N24: MF | O24: =AVERAGE(M24:M25) | P24: =_xlfn.STDEV.S(M24,M25) | Q24: 2 | S24: =+(((K24-I24)/1000)*1000)/10 | T24: =AVERAGE(S24:S25)
A25: 3628 | B25: 50 | C25: T103 | D25: 2 | G25: 14 | H25: 43591 | I25: 5251 | J25: 7996 | K25: 7177 | M25: =+(((J25-I25)-(K25-I25))/(K25-I25))*100 | S25: =+(((K25-I25)/1000)*1000)/10
A26: 4295 | B26: 1 | C26: T103 | D26: 3 | G26: 16 | H26: 43607 | I26: 5301 | J26: 7689 | K26: 7126 | L26: 2 | M26: =+(((J26-I26)-(K26-I26))/(K26-I26))*100 | O26: =AVERAGE(M26:M27) | P26: =_xlfn.STDEV.S(M26,M27) | S26: =+(((K26-I26)/1000)*1000)/10 | T26: =AVERAGE(S26:S27)
A27: 4296 | B27: 2 | C27: T103 | D27: 4 | G27: 16 | H27: 43607 | I27: 5190 | J27: 7602 | K27: 7029 | M27: =+(((J27-I27)-(K27-I27))/(K27-I27))*100 | S27: =+(((K27-I27)/1000)*1000)/10
A28: 4941 | B28: 1 | C28: T103 | D28: 5 | G28: 18 | H28: 43626 | I28: 5301 | J28: 7918 | K28: 7461 | L28: 13 | M28: =+(((J28-I28)-(K28-I28))/(K28-I28))*100 | O28: =AVERAGE(M28:M29) | P28: =_xlfn.STDEV.S(M28,M29) | S28: =+(((K28-I28)/1000)*1000)/10 | T28: =AVERAGE(S28:S29)
A29: 4942 | B29: 2 | C29: T103 | D29: 6 | G29: 18 | H29: 43626 | I29: 5190 | J29: 7592 | K29: 7159 | M29: =+(((J29-I29)-(K29-I29))/(K29-I29))*100 | S29: =+(((K29-I29)/1000)*1000)/10
A30: 5557 | B30: 1 | C30: T103 | D30: 7 | G30: 21 | H30: 43657 | I30: 5301 | J30: 7923 | K30: 7497 | L30: 13 | M30: =+(((J30-I30)-(K30-I30))/(K30-I30))*100 | O30: =AVERAGE(M30:M31) | P30: =_xlfn.STDEV.S(M30,M31) | S30: =+(((K30-I30)/1000)*1000)/10 | T30: =AVERAGE(S30:S31)
A31: 5558 | B31: 2 | C31: T103 | D31: 8 | G31: 21 | H31: 43657 | I31: 5190 | J31: 7912 | K31: 7456 | M31: =+(((J31-I31)-(K31-I31))/(K31-I31))*100 | S31: =+(((K31-I31)/1000)*1000)/10
A32: 5759 | B32: 3 | C32: T103 | D32: 9 | G32: 22 | H32: 43685 | I32: 5258 | J32: 7291 | K32: 7007 | L32: 13 | M32: =+(((J32-I32)-(K32-I32))/(K32-I32))*100 | O32: =AVERAGE(M32:M33) | P32: =_xlfn.STDEV.S(M32,M33) | S32: =+(((K32-I32)/1000)*1000)/10 | T32: =AVERAGE(S32:S33)
A33: 5760 | B33: 3 | C33: T103 | D33: 10 | G33: 22 | H33: 43685 | I33: 5258 | J33: 7368 | K33: 7077 | M33: =+(((J33-I33)-(K33-I33))/(K33-I33))*100 | S33: =+(((K33-I33)/1000)*1000)/10
A34: 3249 | B34: 5 | C34: T104 | D34: 1 | G34: 13 | H34: 43587 | I34: 5236 | J34: 7239 | K34: 6821 | L34: 1 | M34: =+(((J34-I34)-(K34-I34))/(K34-I34))*100 | N34: MF | O34: =AVERAGE(M34:M35) | P34: =_xlfn.STDEV.S(M34,M35) | Q34: 1 | S34: =+(((K34-I34)/1000)*1000)/10 | T34: =AVERAGE(S34:S35)
A35: 3250 | B35: 6 | C35: T104 | D35: 2 | G35: 13 | H35: 43587 | I35: 5259 | J35: 7188 | K35: 6786 | M35: =+(((J35-I35)-(K35-I35))/(K35-I35))*100 | S35: =+(((K35-I35)/1000)*1000)/10
A36: 3975 | B36: 5 | C36: T104 | D36: 3 | G36: 15 | H36: 43599 | I36: 5236 | J36: 7120 | K36: 6744 | M36: =+(((J36-I36)-(K36-I36))/(K36-I36))*100 | O36: =AVERAGE(M36:M37) | P36: =_xlfn.STDEV.S(M36,M37) | S36: =+(((K36-I36)/1000)*1000)/10 | T36: =AVERAGE(S36:S37)
A37: 3976 | B37: 6 | C37: T104 | D37: 4 | G37: 15 | H37: 43599 | I37: 5259 | J37: 7153 | K37: 6787 | M37: =+(((J37-I37)-(K37-I37))/(K37-I37))*100 | S37: =+(((K37-I37)/1000)*1000)/10
A38: 4621 | B38: 5 | C38: T104 | D38: 5 | G38: 17 | H38: 43619 | I38: 5236 | J38: 7185 | K38: 6842 | M38: =+(((J38-I38)-(K38-I38))/(K38-I38))*100 | O38: =AVERAGE(M38:M39) | P38: =_xlfn.STDEV.S(M38,M39) | S38: =+(((K38-I38)/1000)*1000)/10 | T38: =AVERAGE(S38:S39)
A39: 4622 | B39: 6 | C39: T104 | D39: 6 | G39: 17 | H39: 43619 | I39: 5259 | J39: 7206 | K39: 6864 | M39: =+(((J39-I39)-(K39-I39))/(K39-I39))*100 | S39: =+(((K39-I39)/1000)*1000)/10
A40: 5267 | B40: 5 | C40: T104 | D40: 7 | G40: 19 | H40: 43637 | I40: 5236 | J40: 7128 | K40: 6764 | L40: 10 | M40: =+(((J40-I40)-(K40-I40))/(K40-I40))*100 | O40: =AVERAGE(M40:M41) | P40: =_xlfn.STDEV.S(M40,M41) | S40: =+(((K40-I40)/1000)*1000)/10 | T40: =AVERAGE(S40:S41)
...

Sheet PlotEntry
A1: PLOT | B1: ENTRY
A2: 101 | B2: 60
A3: 102 | B3: 85
A4: 103 | B4: 129
A5: 104 | B5: 64
A6: 105 | B6: 95
A7: 106 | B7: 134
A8: 107 | B8: 16
A9: 108 | B9: 108
A10: 109 | B10: 145
A11: 110 | B11: 57
A12: 111 | B12: 123
A13: 112 | B13: 29
... A337: 468 | B337: 145
